Workbook
Name a: #REF!
Name B: #REF!
Name PAC_ORIGINAL: Domínios!#REF!
Name PAC_SELEÇÕES: Domínios!$AG$3:$AG$25
Name status_intervencao: Domínios!$L$3:$L$10
Name status_pleito: Domínios!$L$8:$L$8

Sheet PAC
F1: Quantidade por FASE | J1: QTD TOTAL | K1: INVESTIMENTO TOTAL
F2: CAPTAÇÃO | G2: LICITAÇÃO | H2: EXECUÇÃO | I2: CONCLUÍDAS | K2: VALOR SOLICITADO FINANCIAMENTO | L2: VALOR SOLICITADO OGU | M2: APOIADO | N2: CONTRAPARTIDA | O2: COMPLEMENTAR | P2: FINANCIAMENTO | Q2: PLANEJAMENTO ORÇAMENTÁRIO DESCONSIDERANDO AS OBRAS JÁ CONTRATADAS | R2: APOIADO CONTRATADO | S2: CONTRAPARTIDA CONTRATADA | T2: COMPLEMENTAR CONTRATADO | U2: FINANCIAMENTO CONTRATADO | V2: VALOR CONTRATADO | W2: INVESTIMENTO TOTAL
F3: =SUBTOTAL(9,PAC!$BB$6:$BB$581) -> 0 | G3: =SUBTOTAL(9,PAC!$BC$6:$BC$581) -> 0 | H3: =SUBTOTAL(9,PAC!$BD$6:$BD$581) -> 1 | I3: =SUBTOTAL(9,PAC!$BE$6:$BE$581) -> 0 | J3: =SUBTOTAL(3,J6:J581) -> 1 | K3: =SUBTOTAL(9,PAC!K$6:K$581) -> 0 | L3: =SUBTOTAL(9,PAC!L$6:L$581) -> 0 | M3: =SUBTOTAL(9,PAC!M$6:M$581) -> 11440559 | N3: =SUBTOTAL(9,PAC!N$6:N$581) -> 139742.41 | O3: =SUBTOTAL(9,PAC!O$6:O$581) -> 1915931 | P3: =SUBTOTAL(9,PAC!P$6:P$581) -> 0 | Q3: =SUBTOTAL(9,PAC!$BF$6:$BF$581) -> 0 | R3: =SUBTOTAL(9,PAC!R$6:R$581) -> 10947985 | S3: =SUBTOTAL(9,PAC!S$6:S$581) -> 139742.41 | T3: =SUBTOTAL(9,PAC!T$6:T$581) -> 1412523.9 | U3: =SUBTOTAL(9,PAC!U$6:U$581) -> 0 | V3: =SUBTOTAL(9,PAC!V$6:V$581) -> 12500251 | W3: =SUBTOTAL(9,PAC!W$6:W$581) -> 12500251
A5: ITEM | B5: ANO DE CADASTRO | C5: TIPO | D5: PAC | E5: DESCRIÇÃO | F5: EIXO | G5: OBJETO | H5: SECRETARIA/ ÓRGÃO | I5: ORGÃO EXECUTOR | J5: MUNICÍPIO | K5: VALOR SOLICITADO (FINANCIAMENTO) | L5: VALOR SOLICITADO (OGU) | M5: APOIADO | N5: CONTRAPARTIDA | O5: COMPLEMENTAR | P5: FINANCIAMENTO | Q5: PLANEJAMENTO ORÇAMENTÁRIO | R5: APOIADO CONTRATADO | S5: CONTRAPARTIDA CONTRATADA | T5: COMPLEMENTAR CONTRATADO | U5: FINANCIAMENTO CONTRATADO | V5: VALOR CONTRATADO | W5: INVESTIMENTO TOTAL | X5: EMPRESA CONTRATADA | Y5: FONTE DE RECURSO | Z5: FONTE DE FINANCIAMENTO | AA5: PRAZO EXECUÇÃO (MESES) | AB5: FASE | AC5: STATUS | AD5: PRAZO DE CONCLUSÃO DA FASE | AE5: AVANÇO DA OBRA (%) | AF5: PENDÊNCIAS / TAREFA | AG5: PROVIDÊNCIAS (DATAS) | AH5: PRAZO DA PENDÊNCIA / TAREFA | AI5: PRÓXIMOS PASSOS | AJ5: Nº DA PROPOSTA PAC | AK5: Nº DO TERMO DE COMP. (TC) / CT FINANCIAMENTO | AL5: CLÁUSULA SUSPENSIVA | AM5: MOTIVO DA CLÁUSULA SUSPENSIVA | AN5: VIGÊNCIA | AO5: LINK_MONITORA | AP5: LINK_LOCALIZAÇÃO | AQ5: STATUS ANTERIOR SELEÇÃO 2023 | AR5: AVISO DE LICITAÇÃO | AS5: ABERTURA DE LICITAÇÃO | AT5: PREVISÃO DE CONTRATAÇÃO | AU5: EMISSÃO DE O.S. | AV5: DATA DE CONCLUSÃO ORIGINAL | AW5: PREVISÃO DE CONCLUSÃO ATUAL | AX5: OBSERVAÇÕES | AY5: DETALHE DO STATUS | AZ5: DATA DA SELEÇÃO | BA5: DET. DO PROJETO - PAC | BB5: CAPTAÇÃO | BC5: LICITAÇÃO | BD5: OBRA | BE5: CONCLUÍDAS | BF5: PLANEJAMENTO ORÇAMENTÁRIO SEM O VALOR CONTRATADO
A6: =ROW()-5 -> 1 | B6: 2023 | C6: OBRA | D6: PAC ORIGINAL | E6: Adutora da Fé – 1ª Etapa | F6: Água Para Todos | G6: Adutora da Fé | H6: GESTÃO FEDERAL | I6: 07 - Gov. Federal - CODEVASF | J6: Bom Jesus da Lapa | M6: 47303701 | Q6: =SUM(PAC!$M6:$P6) -> 47303701 | W6: =IF(PAC!$V6>0,PAC!$V6,PAC!$Q6) -> 47303701 | Y6: OGU | AB6: F04 - CONCLUÍDA | AC6: 18 - INAUGURADA | AE6: 100 | AF6: Publicar Contrato de Execução | AY6: Obra inaugurada em 07/02/25 pelo Presidente Lula. | BB6: =IFERROR(IF(PAC!$AB6="F01 - CAPTAÇÃO DE RECURSO",1,""),"") | BC6: =IFERROR(IF(PAC!$AB6="F02 - LICITAÇÃO",1,""),"") | BD6: =IFERROR(IF(PAC!$AB$6:$AB$581="F03 - EXECUÇÃO DO OBJETO",1,""),"") | BE6: =IFERROR(IF(PAC!$AB$6:$AB$581="F04 - CONCLUÍDA",1,""),"") -> 1 | BF6: =IF(PAC!$V6>0,0,PAC!$Q6) -> 47303701
A7: =ROW()-5 -> 2 | B7: 2023 | C7: OBRA | D7: PAC ORIGINAL | E7: Adutora da Fé – 2ª Etapa | F7: Água Para Todos | G7: Adutora da Fé | H7: GESTÃO FEDERAL | I7: 07 - Gov. Federal - CODEVASF | J7: Bom Jesus da Lapa | M7: 2.5883994e+08 | Q7: =SUM(PAC!$M7:$P7) -> 2.5883994e+08 | W7: =IF(PAC!$V7>0,PAC!$V7,PAC!$Q7) -> 2.5883994e+08 | Y7: OGU | AB7: F03 - EXECUÇÃO DO OBJETO | AC7: 03 - AGUARDANDO ORDEM DE SERVIÇO | AI7: Iniciar as obras | AX7: Informação recebida em 13/08/2025: _ A responsabilidade pela execução da totalidade da obra será da Eletrobrás, que fará a contratação da empresa construtora. _ O projeto inicial é da CODEVASF, porém a Eletrobrás contratou uma empresa para revisar o Projeto Básico, tendo em vista dificuldades para a execução da obra em trechos urbanos (municípios de Riacho de Santana e Igaporã) com interferência na malha rodoviária administrada pelo DNIT. _ Foi aberto requerimento para início do procedimento da Licença dessa fase da obra, porém está pendente até a conclusão da revisão do projeto. Assim, ainda não há expectativa para início das obras da 2ª etapa e do cronograma para a sua implantação. | AY7: (Obra contratada pela Eletrobrás - contrato assinado em 21/01/25 - Inf. Codevasf) Verificar a coluna de observações "...não há expectativa para início das obras da 2ª etapa e do cronograma para a sua implantação." | BB7: =IFERROR(IF(PAC!$AB7="F01 - CAPTAÇÃO DE RECURSO",1,""),"") | BC7: =IFERROR(IF(PAC!$AB7="F02 - LICITAÇÃO",1,""),"") | BD7: =IFERROR(IF(PAC!$AB$6:$AB$581="F03 - EXECUÇÃO DO OBJETO",1,""),"") -> 1 | BE7: =IFERROR(IF(PAC!$AB$6:$AB$581="F04 - CONCLUÍDA",1,""),"") | BF7: =IF(PAC!$V7>0,0,PAC!$Q7) -> 2.5883994e+08
A8: =ROW()-5 -> 3 | B8: 2023 | C8: OBRA | D8: PAC ORIGINAL | E8: Aeroporto de Barreiras (INFRA) | F8: Infraestrutura | G8: Aeroporto (INFRA) | H8: SEINFRA | I8: 01 - Gov. Estado - SEINFRA | J8: Barreiras | L8: 100000000 | M8: 44086568 | Q8: =SUM(PAC!$M8:$P8) -> 44086568 | V8: 44086568 | W8: =IF(PAC!$V8>0,PAC!$V8,PAC!$Q8) -> 44086568 | X8: CONSORCIO AEROPORTO DE BARREIRAS PORTICO - ETERC - EBSA | Y8: OGU | AA8: 11 | AB8: F03 - EXECUÇÃO DO OBJETO | AC8: 02 - ANDAMENTO | AD8: 46326 | AE8: 42 | AF8: Execução da Obra | AG8: Conforme NT de 12/08 devido às chuvas, foi formalizado aditivo de prazo reprogramando a conclusão da obra de 30/09/26 para OUT/26. Obras de terraplenagem para ampliação da cabeceira, em fase final. Serão iniciados os serviços de execução das camadas de sub-base e base. OBSERVAÇÕES: - Existem tratativas técnicas para atender às necessidades da LATAM de iniciar as operações do Aeroporto em NOV/26. Segundo a DTE, a operação independe do conclusão do TPS. Conforme DTE/SEINFRA, não será possível a compatibilização dos cronogramas de execução de INFRA e TPS para entrega total do equipamento em data única, devido às demandas específicas do TPS. | AH8: 46326 | AI8: Monitorar andamento das obras. | AK8: 06/2018 | AO8: https://governodabahia.plataformatarget.com.br/web/a1391b0c-f58d-4537-8193-51235efc7385/home | AP8: https://maps.app.goo.gl/y2A6Z8frmTDtxnL48 | AR8: 45584 | AS8: 45667 | AT8: 45806 | AU8: 45833 | AV8: 46163 | AW8: 46326 | AX8: 16/06/2026 - Conforme Ofício GASEC nº 271/2025, de 05/06/2025, a SEINFRA solicitou à SAC a supressão do TPS e equipamentos e mobiliários do TC 06/2018, para que os mesmos sejam executados com recursos próprios, mantendo apenas a INFRA com recurso do PAC. Processo SEI nº: 024.2058.2024.0008514-17 - Objeto: Execução de obras de reforma e ampliação da PPD, reforma e adequação da taxiway, construção do novo pátio de aeronaves e serviços complementares de: drenagem e infra do balizamento noturno e auxílios à navegação, do Aeroporto de Barreiras - Dom Ricardo Weberberger - Bahia (SNBR). Fonte de Recurso - Governo Federal - Fundo Nacional de Aviação (FNAC) (INFRA + Equipamentos)*: R$ 65,7 milhões (VALOR INICIALMENTE APROVADO E APOIADO CONFORME SELEÇÃO PAC EM 2023) VIGÊNCIA DO TC 31/12/2024. Licença de Alteração, Portaria INEMA n° 30.754, vigência 14/11/2028) Conforme Seinfra (27/09 - Grupo Whatsapp) a Concessão pemanecerá com a Agerba, vigência até 03/08/2032. 07/10 - Edital analisado pela PGE e SAEB, uma vez que o BB ainda não disponibilizou Plataforma para licitação concorrência eletrônica para julgamento técnica e preço. Conforme SEINFRA, não há previsão para o certame de equipamentos/mobiliários; 18/09 - Autorização da SAC para início do processo licitatório, com glosa e ressalvas, conforme Ofício 529/2024/SAC-MPOR. 13/09 - Entregues à SAC (plataforma) relatório assinado pela Seinfra e licença ambiental. 02/09 - Adequações de orçamento entregues na plataforma da SAC, pendente parecer final. Financiamento: FNAC | AY8: 16/06/2026 - Conforme Ofício GASEC nº 271/2025, de 05/06/2025, a SEINFRA solicitou à SAC a supressão do TPS e equipamentos e mobiliários do TC 06/2018, para que os mesmos sejam executados com recursos próprios, mantendo apenas a INFRA com recurso do PAC. 09/12/25 - Percentual de execução atualizado 16,24%, conforme retorno DTE (Whatsapp Roberval). 02/09/25 - Obra em andamento ainda sem % de execução. Conforme Diretoria de Terminais a obra foi iniciada em 15/08/25, um dia após emissão de NOTAM pela ANAC (autorização necessária para início) e não após emissão da O.S., tendo a previsão de conclusão ajustada para ABR/26. 25/06/25 - Assinatura da Ordem de Serviço. 30/05/25 - Publicado resumo de contrato, execução 330 dias. Pendente emissão O.S. | BB8: =IFERROR(IF(PAC!$AB8="F01 - CAPTAÇÃO DE RECURSO",1,""),"") | BC8: =IFERROR(IF(PAC!$AB8="F02 - LICITAÇÃO",1,""),"") | BD8: =IFERROR(IF(PAC!$AB$6:$AB$581="F03 - EXECUÇÃO DO OBJETO",1,""),"") -> 1 | BE8: =IFERROR(IF(PAC!$AB$6:$AB$581="F04 - CONCLUÍDA",1,""),"") | BF8: =IF(PAC!$V8>0,0,PAC!$Q8) -> 0
A9: =ROW()-5 -> 4 | B9: 2023 | C9: EQUIPAMENTOS | D9: PAC ORIGINAL | E9: Aeroporto de Barreiras (EQUIPAMENTOS DE BALIZAMENTO - PISTA/INFRA) Sinalização: iluminação de pátio, luminoso PPD e TWY, Biruta, Farol, Papi, etc. | F9: Infraestrutura | G9: Aeroporto (EQUIPAMENTOS) | H9: SEINFRA | I9: 01 - Gov. Estado - SEINFRA | J9: Barreiras | N9: 4050508.4 | Q9: =SUM([1]PAC!$M9:$P9) -> 4050508.4 | V9: 3300969.6 | W9: =IF(PAC!$V9>0,PAC!$V9,PAC!$Q9) -> 3300969.6 | X9: METROL ENGENHARIA LTDA. | Y9: CONTRAPARTIDA | AA9: 3 | AB9: F03 - EXECUÇÃO DO OBJETO | AC9: 02 - ANDAMENTO | AD9: 46387 | AE9: 0 | AF9: Execução da Obra | AG9: CONFORME DEFINIDO EM REUNIÃO COM MINISTÉRIO, GOVERNADOR E SECRETÁRIOS DA C.CIVIL E SEINFRA (29/07/26), OS EQUIPAMENTOS MOBILIÁRIOS FICARÃO SOB A RESPONSABILIDADE DA CONCESSIONÁRIA. O ESTADO NÃO FARÁ AQUISIÇÃO. Contrato publicado em 18/09 e OS. assinada em 21/09/2026. Licitação homologada e adjudicada, com pulicação no DOE em 20/08/2026. Empresa vencedora: Metrol Engenharia Ltda. Publicado AVISO DE LICITAÇÃO - PREGÃO ELETRÔNICO Nº 1/2026 - SEINFRA/SIT - BB Nº 1090760, em 03/04/2026. Abertura dos envelopes ocorrida em 22/04/26. | AH9: 46387 | AI9: CONFORME DEFINIDO EM REUNIÃO COM MINISTÉRIO, GOVERNADOR E SECRETÁRIOS DA C.CIVIL E SEINFRA (29/07/26), OS EQUIPAMENTOS MOBILIÁRIOS FICARÃO SOB A RESPONSABILIDADE DA CONCESSIONÁRIA. O ESTADO NÃO FARÁ AQUISIÇÃO. Assinatura do contrato com a empresa para iniciar serviços de instalação da sinalização. | AO9: https://governodabahia.plataformatarget.com.br/web/fbb30a88-ec24-4177-87a2-2b54f6b0731e | AP9: https://maps.app.goo.gl/y2A6Z8frmTDtxnL48 | AR9: 46115 | AS9: 46134 | AT9: 46283 | AU9: 46286 | AV9: 46387 | AW9: 46387 | AX9: CONFORME DEFINIDO EM REUNIÃO COM MINISTÉRIO, GOVERNADOR E SECRETÁRIOS DA C.CIVIL E SEINFRA (29/07/26), OS EQUIPAMENTOS MOBILIÁRIOS FICARÃO SOB A RESPONSABILIDADE DA CONCESSIONÁRIA. O ESTADO NÃO FARÁ AQUISIÇÃO. 16/06/2026 - Conforme Ofício GASEC nº 271/2025, de 05/06/2025, a SEINFRA solicitou à SAC a supressão do TPS e equipamentos e mobiliários do TC 06/2018, para que os mesmos sejam executados com recursos próprios, mantendo apenas a INFRA com recurso do PAC. Processo SEI nº: 024.2058.2024.0008514-17 - Objeto: Execução de obras de reforma e ampliação da PPD, reforma e adequação da taxiway, construção do novo pátio de aeronaves e serviços complementares de: drenagem e infra do balizamento noturno e auxílios à navegação, do Aeroporto de Barreiras - Dom Ricardo Weberberger - Bahia (SNBR). Fonte de Recurso - Governo Federal - Fundo Nacional de Aviação (FNAC) (INFRA + Equipamentos)*: R$ 65,7 milhões (VALOR INICIALMENTE APROVADO E APOIADO CONFORME SELEÇÃO PAC EM 2023) VIGÊNCIA DO TC 31/12/2024. Licença de Alteração, Portaria INEMA n° 30.754, vigência 14/11/2028) Conforme Seinfra (27/09 - Grupo Whatsapp) a Concessão pemanecerá com a Agerba, vigência até 03/08/2032. Financiamento: FNAC | AY9: CONFORME DEFINIDO EM REUNIÃO COM MINISTÉRIO, GOVERNADOR E SECRETÁRIOS DA C.CIVIL E SEINFRA (29/07/26), OS EQUIPAMENTOS MOBILIÁRIOS FICARÃO SOB A RESPONSABILIDADE DA CONCESSIONÁRIA. O ESTADO NÃO FARÁ AQUISIÇÃO. 16/06/2026 - Conforme Ofício GASEC nº 271/2025, de 05/06/2025, a SEINFRA solicitou à SAC a supressão do TPS e equipamentos e mobiliários do TC 06/2018, para que os mesmos sejam executados com recursos próprios, mantendo apenas a INFRA com recurso do PAC. 08/01/26 - Segundo SEINFRA, a previsão para a divulgação do aviso de licitação da Sinalização é MAR/26, permanecendo sem data a do Mobiliário. 05/11 - Conforme SEINFRA, o novo prazo para publicação de licitação é NOV/25 (iluminação de pátio, luminoso PPD e TWY, Biruta, Farol, Papi, etc.). OBS: Prazo inicial SET/25 foi alterado, devido atraso na apresentação de documentação pela empresa contratada. O TR está em elaboração, o mesmo deve ser encaminhado à PGE após conclusão; Mobiliário: Licitação depende da conclusão do projeto executivo (até DEZ/25) em elaboração pela empresa executora do TPS, para levantamento das necessidades e elaboração de TR e Edital. | BB9: =IFERROR(IF(PAC!$AB9="F01 - CAPTAÇÃO DE RECURSO",1,""),"") | BC9: =IFERROR(IF(PAC!$AB9="F02 - LICITAÇÃO",1,""),"") | BD9: =IFERROR(IF(PAC!$AB$6:$AB$581="F03 - EXECUÇÃO DO OBJETO",1,""),"") -> 1 | BE9: =IFERROR(IF(PAC!$AB$6:$AB$581="F04 - CONCLUÍDA",1,""),"") | BF9: =IF(PAC!$V9>0,0,PAC!$Q9) -> 0
A10: =ROW()-5 -> 5 | B10: 2023 | C10: OBRA | D10: PAC ORIGINAL | E10: Aeroporto de Barreiras (TPS) | F10: Infraestrutura | G10: Aeroporto (TPS) | H10: SEINFRA | I10: 01 - Gov. Estado - SEINFRA | J10: Barreiras | N10: 19342946 | Q10: =SUM(PAC!$M10:$P10) -> 19342946 | V10: 19342946 | W10: =IF(PAC!$V10>0,PAC!$V10,PAC!$Q10) -> 19342946 | X10: CONSORCIO PROJETISTA BARREIRAS | Y10: CONTRAPARTIDA | AA10: 16 | AB10: F03 - EXECUÇÃO DO OBJETO | AC10: 02 - ANDAMENTO | AD10: 46326 | AE10: 52 | AF10: Execução da Obra | AG10: Em fase final da montagem dos pilares metálicos para iniciar cobertura. Novo término de obra previsto para OUT/2026 (medições estão abaixo do desejado). Obra do Terminal iniciada em Jan/26, em regime de contratação integrada. OBSERVAÇÕES: - Existem tratativas técnicas para atender às necessidades da LATAM de iniciar as operações do Aeroporto em NOV/26. Segundo a DTE, a operação independe do conclusão do TPS. - CONFORME DEFINIDO EM REUNIÃO COM MINISTÉRIO, GOVERNADOR E SECRETÁRIOS DA C.CIVIL E SEINFRA (29/07/26), OS EQUIPAMENTOS MOBILIÁRIOS FICARÃO SOB A RESPONSABILIDADE DA CONCESSIONÁRIA. O ESTADO NÃO FARÁ AQUISIÇÃO. Segundo DTE/SEINFRA, não será possível a compatibilização dos cronogramas de execução de INFRA e TPS para entrega total do equipamento em data única, devido às demandas específicas do TPS. | AH10: 46326 | AI10: Monitorar andamento das obras. | AO10: https://governodabahia.plataformatarget.com.br/web/aadaf15d-57f0-4185-8794-6c12c73234bb/home | AP10: https://maps.app.goo.gl/y2A6Z8frmTDtxnL48 | AR10: 45505 | AS10: 45597 | AT10: 45859 | AU10: 45862 | AV10: 46264 | AW10: 46326 | AX10: 16/06/2026 - Conforme Ofício GASEC nº 271/2025, de 05/06/2025, a SEINFRA solicitou à SAC a supressão do TPS e equipamentos e mobiliários do TC 06/2018, para que os mesmos sejam executados com recursos próprios, mantendo apenas a INFRA com recurso do PAC. Orçamento Inicial - R$ 25 milhões. SEI: 024.2058.2024.0005354-18 30/11/24 - Remarcada sessão para divulgação do julgamento das propostas técnicas e de preços de 03/12 para 20/12. 13/11/24 - Remarcada sessão para divulgação do julgamento das propostas técnicas e de preços de 14/11 para 03/12. 01/08 - Publicado Aviso de Licitação CP 027/2024, referente à Contratação integrada para elaboração de Projetos Básicos, Executivos e Construção de Terminal de Passageiros. Abertura 01/11/2024. Elaboração do Projeto básico de TPS e EQUIPAMENTOS/MOBILIÁRIO pela EGIS, foi suspenso, devido a não conclusão, conforme contratação. Definido que o Estado fará licitação com recursos próprios na modalidade Contratação Integrada. TR e Edital para a licitação do TPS finalizados e analisados pela PGE. | AY10: 16/06/2026 - Conforme Ofício GASEC nº 271/2025, de 05/06/2025, a SEINFRA solicitou à SAC a supressão do TPS e equipamentos e mobiliários do TC 06/2018, para que os mesmos sejam executados com recursos próprios, mantendo apenas a INFRA com recurso do PAC. 02/09/25 - Obra em início de mobilização (regime de contratação integrada). Previsão de conclusão conforme Monitora. 24/07/25 - Assinatura da Ordem de Serviço. 23/07/25 - Publicado contrato para elaboração de Projetos Básicos, Executivos e Construção de TPS e edificações auxiliares do Aeroporto de Barreiras, execução 480 dias. | BB10: =IFERROR(IF(PAC!$AB10="F01 - CAPTAÇÃO DE RECURSO",1,""),"") | BC10: =IFERROR(IF(PAC!$AB10="F02 - LICITAÇÃO",1,""),"") | BD10: =IFERROR(IF(PAC!$AB$6:$AB$581="F03 - EXECUÇÃO DO OBJETO",1,""),"") -> 1 | BE10: =IFERROR(IF(PAC!$AB$6:$AB$581="F04 - CONCLUÍDA",1,""),"") | BF10: =IF(PAC!$V10>0,0,PAC!$Q10) -> 0
A11: =ROW()-5 -> 6 | B11: 2023 | C11: OBRA | D11: PAC ORIGINAL | E11: Barragem de Catolé | F11: Água Para Todos | G11: Barragem | H11: SIHS | I11: 05 - Gov. Estado - EMBASA | J11: Barra do Choça | M11: 1.2737858e+08 | N11: 1.0810276e+08 | O11: 6962472.3 | Q11: =SUM(PAC!$M11:$P11) -> 2.4244381e+08 | R11: 1.2737858e+08 | S11: 1.0810276e+08 | T11: 6962472.3 | V11: 2.4244381e+08 | W11: =IF(PAC!$V11>0,PAC!$V11,PAC!$Q11) -> 2.4244381e+08 | X11: CONSÓRCIO CNA (Constituído pelas empresas, CETENCO ENGENHARIA S.A, NOVATEC CONSTRUÇÕES E EMPREENDIMENTOS LTDAe AJDV ENGENHARIA S.A) | Y11: OGU CONTRAPARTIDA COMPLEMENTAR | AA11: 30 | AB11: F03 - EXECUÇÃO DO OBJETO | AC11: 02 - ANDAMENTO | AD11: 46438 | AE11: 70 | AF11: Execução da Obra | AG11: Monitorar a execução da obra | AK11: 0394941-94/2012 | AP11: https://maps.app.goo.gl/tyvHyi6RUcoziRid7 | AR11: 45449 | AS11: 45477 | AT11: 45530 | AU11: 45537 | AV11: 46438 | AW11: 46438 | AX11: Regime de Execução: Empreitada por Preço Global A contrapartida e o valor complementar são de responsabilidade da EMBASA. Ordem de Serviço emitida em 02/09/2024 - retomada de obra (informação EMBASA); Contrato assinado em 27/8/24 com o Consórcio CNA (Cetenco Eng. S.A, Novatec Construções e Emp. Ltda e AJDV Engenhariada - valor R$ 242.443.812,89 | AY11: Obra em execução - PAC II OGU. Valor Termo de Compromisso: R$ 249.132.763,63 Avanço físico Termo de Compromisso: 68,0% O novo modelo de QCI, associando apenas contratos executados e em execução, possibilitou reestruturar a condição dos recursos retidos, assim como o último desbloqueio realizado, eliminou as glosas do empreendimento. Além disso, cabe esclarecer que o valor da Embasa é superior ao acompanhado pela Caixa pois é composto pelo valor contratado mais o valor exclusivo de recursos próprios (Extra TC). | BB11: =IFERROR(IF(PAC!$AB11="F01 - CAPTAÇÃO DE RECURSO",1,""),"") | BC11: =IFERROR(IF(PAC!$AB11="F02 - LICITAÇÃO",1,""),"") | BD11: =IFERROR(IF(PAC!$AB$6:$AB$581="F03 - EXECUÇÃO DO OBJETO",1,""),"") -> 1 | BE11: =IFERROR(IF(PAC!$AB$6:$AB$581="F04 - CONCLUÍDA",1,""),"") | BF11: =IF(PAC!$V11>0,0,PAC!$Q11) -> 0
A12: =ROW()-5 -> 7 | B12: 2023 | C12: OBRA | D12: PAC ORIGINAL | E12: Barragem de Baraúnas / Vazante | F12: Água Para Todos | G12: Barragem | H12: SIHS | I12: 06 - Gov. Estado - CERB | J12: Seabra | M12: 48490064 | N12: 7026635.5 | O12: =20446802.96+11012079.78 -> 31458883 | Q12: =SUM(PAC!$M12:$P12) -> 86975582 | R12: 48490064 | S12: 7026635.5 | T12: =20446802.96+11012079.78 -> 31458883 | V12: 86975582 | W12: =IF(PAC!$V12>0,PAC!$V12,PAC!$Q12) -> 86975582 | X12: Consórcio Barragem Baráunas (RCA Construções e Construtora Augusto Velloso S.A) | Y12: OGU CONTRAPARTIDA COMPLEMENTAR | AB12: F03 - EXECUÇÃO DO OBJETO | AC12: 02 - ANDAMENTO | AD12: 46325 | AE12: 96.13 | AF12: Execução da Obra | AG12: Monitorar a execução da obra | AH12: 46325 | AK12: 421922-59/2013 | AP12: https://maps.app.goo.gl/sTyVoZkV6bZiCSo28 | AR12: 44310 | AS12: 44378 | AT12: 44497 | AU12: 44495 | AV12: 44860 | AW12: 46325 | AX12: CONTRATOS COMPANHIA DE ENGENHARIA HÍDRICA E DE SANEAMENTO DA BAHIA - CERB Extrato do Termo Aditivo nº 137/2025 ao Contrato de Empreitada nº 045/2021 - Processo SEI nº 039.0792.2025.0006319-16. Partes: CERB e o Consórcio Barragem de Baraúnas. Objeto: Alteração do contrato originário com o 2º Reequilíbrio Econômico-financeiro, no valor de R$ 11.012.079,78, que passa a ter o valor total de R$ 99.802.320,54. Data da Assinatura: 04.12.2025. JAYME DE SOUZA VIEIRA LIMA FILHO - Diretor Presidente-CERB. | AY12: Termo Aditivo de Prazo Proposto: Prazo: 122 Dias Final do Prazo de Execução: 30/10/2026 Nova Vigência: 16/12/2026 | BB12: =IFERROR(IF(PAC!$AB12="F01 - CAPTAÇÃO DE RECURSO",1,""),"") | BC12: =IFERROR(IF(PAC!$AB12="F02 - LICITAÇÃO",1,""),"") | BD12: =IFERROR(IF(PAC!$AB$6:$AB$581="F03 - EXECUÇÃO DO OBJETO",1,""),"") -> 1 | BE12: =IFERROR(IF(PAC!$AB$6:$AB$581="F04 - CONCLUÍDA",1,""),"") | BF12: =IF(PAC!$V12>0,0,PAC!$Q12) -> 0
A13: =ROW()-5 -> 8 | B13: 2023 | C13: OBRA | D13: PAC ORIGINAL | E13: Barragem de Morrinhos | F13: Água Para Todos | G13: Barragem | H13: SIHS | I13: 06 - Gov. Estado - CERB | J13: Piripá | L13: 1.3618782e+08 | M13: 1.3618782e+08 | Q13: =SUM(PAC!$M13:$P13) -> 1.3618782e+08 | V13: 1.2942677e+08 | W13: =IF(PAC!$V13>0,PAC!$V13,PAC!$Q13) -> 1.2942677e+08 | X13: CONSÓRCIO BARRAGEM MORRINHOS | Y13: OGU | AA13: 21 | AB13: F02 - LICITAÇÃO | AC13: 04 - LICITAÇÃO /CONTRATAÇÃO | AD13: 46356 | AF13: Enviar documentos para atendimento à Cláusula Suspensiva | AG13: Formalização do Termo Aditivo para acréscimo da contrapartida estadual. Ordem de Serviço parcial emitida em 03/07/2026. A CERB está cumprindo as condicionantes exigidas para obtenção da Licença de Instalação. | AH13: 46356 | AI13: A emissão da Ordem de Serviço definitiva está condicionada à obtenção da licença ambiental, com previsão para agosto de 2027. | AJ13: 092/2024 | AK13: 958195/2024 | AL13: 03 - Cláusula Vigente | AM13: Devido ao acréscimo de serviços para atendimento a licença ambiental o valor inicial da obra foi alterado. O Governo do Estado da Bahia conseguiu destinar a dotação complementar para que a execução da obra da Barragem de Morrinhos seja realizada com o êxito esperado pelo Governo Federal e Estadual. Para tanto se faz necessária a formalização do Termo Aditivo para acréscimo da contrapartida estadual. | AN13: 46356 | AR13: 46097 | AS13: 46120 | AT13: 46206 | AX13: Em processo de formalização do Termo Aditivo de readequação do Plano de Trabalho, bem como a ampliação do valor, com valor da contrapartida Estadual para Execução da Obra: R$ 32.000.000,00 (trinta e dois milhões de reais), para participação, a título de Contrapartida Financeira, no repasse de recursos destinados a Obra e Implantação da Barragem de Morrinhos Ordem de Serviço parcial emitida em 03/07/2026. A CERB está cumprindo as condicionantes exigidas para obtenção da Licença de Instalação. A emissão da Ordem de Serviço definitiva está condicionada à obtenção da licença ambiental, com previsão para agosto de 2027. | AY13: SECRETARIA DE INFRAESTRUTURA HÍDRICA E SANEAMENTO - SIHS COMPANHIA DE ENGENHARIA HÍDRICA E DE SANEAMENTO DA BAHIA - CERB Extrato de Contrato nº 052/2026. Processo Sei nº 039.0781.2024.0005392-92. Partes: CERB e CONSÓRCIO BARRAGEM MORRINHOS. Objeto: contratação de empresa especializada para execução da obra de implantação da Barragem de Morrinhos, situada na Bacia do Rio Gavião, nos Municípios de Piripá, Presidente Jânio Quadros, Condeúba e Cordeiros, no Estado da Bahia. Fundamento: Licitação Pública nº 2026007. Valor: R$ 129.426.772,84. Prazo de execução: 630dias, iniciando-se sua contagem a partir do 7º (sétimo) dia após a emissão da Ordem de Serviço expedida pela CERB. Prazo de vigência: 750 dias, contado do primeiro dia útil subsequente à sua assinatura. Data da Assinatura: 03/07/2026. Larissa Gomes Moraes - Diretora Presidente -CERB. | BB13: =IFERROR(IF(PAC!$AB13="F01 - CAPTAÇÃO DE RECURSO",1,""),"") | BC13: =IFERROR(IF(PAC!$AB13="F02 - LICITAÇÃO",1,""),"") -> 1 | BD13: =IFERROR(IF(PAC!$AB$6:$AB$581="F03 - EXECUÇÃO DO OBJETO",1,""),"") | BE13: =IFERROR(IF(PAC!$AB$6:$AB$581="F04 - CONCLUÍDA",1,""),"") | BF13: =IF(PAC!$V13>0,0,PAC!$Q13) -> 0
A14: =ROW()-5 -> 9 | B14: 2023 | C14: OBRA | D14: PAC ORIGINAL | E14: Barragem de Rio da Caixa | F14: Água Para Todos | G14: Barragem | H14: SIHS | I14: 06 - Gov. Estado - CERB | J14: Rio do Pires | L14: 1.231656e+08 | M14: 1.231656e+08 | O14: 12675392 | Q14: =SUM(PAC!$M14:$P14) -> 1.3584099e+08 | R14: 1.1750931e+08 | T14: 1272765.9 | V14: 1.1878208e+08 | W14: =IF(PAC!$V14>0,PAC!$V14,PAC!$Q14) -> 1.1878208e+08 | X14: Consórcio Barragem Rio da Caixa (RCA, COASTAL e CMR4) | Y14: OGU COMPLEMENTAR | AA14: 21 | AB14: F03 - EXECUÇÃO DO OBJETO | AC14: 02 - ANDAMENTO | AD14: 46590 | AE14: 13.52 | AF14: Execução da Obra | AG14: Monitorar a execução da obra Em análise pelo Ministério a solicitação de PAD - Planilha de Ajustes e Desvios. | AH14: 46590 | AI14: Monitorar a execução da obra | AJ14: 089/2024 | AK14: 958204/2024 | AL14: 01 - Retirada Total | AN14: 46618 | AP14: https://maps.app.goo.gl/DMdCohB9uWSEGHvL6 | AR14: 44792 | AS14: 44817 | AT14: 45376 | AU14: 45553 | AV14: 46198 | AW14: 46590 | AX14: Licitação pretérita EXTRATO De termo aditivo Publicado em: 05/02/2025 | Edição: 25 | Seção: 3 DOU Alteração no valor do repasse do MIDR que passa a ser R$ 123.165.596,20, sendo apenas R$117.509.310,18 para a obra necessitando assim uma complementação financeira do Estado de R$ 1.272.765,95 para atender o valor de contrato para execução da obra. Emitida OS Nº006/2024 - complementar em 18/09/2024. Esta OS é complementar a OS 006/2024 Parcial, de 25/04/2024 ; | AY14: Monitorar a execução da obra Extrato do Termo Aditivo nº 093/2026 ao Contrato nº 022/2024 - Processo SEI n° 039.0795.2026.0004750-71. Partes: CERB e o Consórcio Barragem Rio da Caixa. Objeto: Objeto: Acréscimo no valor do contrato originário em R$ 11.402.625,93, e com a alteração o valor do contrato passa a ser de R$ 130.184.702,06. Data da Assinatura: 29/07/2026.Larissa Gomes Moraes - Diretora Presidente/CERB. | BB14: =IFERROR(IF(PAC!$AB14="F01 - CAPTAÇÃO DE RECURSO",1,""),"") | BC14: =IFERROR(IF(PAC!$AB14="F02 - LICITAÇÃO",1,""),"") | BD14: =IFERROR(IF(PAC!$AB$6:$AB$581="F03 - EXECUÇÃO DO OBJETO",1,""),"") -> 1 | BE14: =IFERROR(IF(PAC!$AB$6:$AB$581="F04 - CONCLUÍDA",1,""),"") | BF14: =IF(PAC!$V14>0,0,PAC!$Q14) -> 0
A15: =ROW()-5 -> 10 | B15: 2023 | C15: OBRA | D15: PAC ORIGINAL | E15: Cont. empresa p/ elaboração de proj. executivo e execução das obras p/ implementação da tomada d’água no RC500 e do canal CP-500/2 – Perímetro de Irrigação Salitre, p/ integração ao Canal do Sertão Baiano. | F15: Água Para Todos | G15: Canal do Sertão | H15: GESTÃO FEDERAL | I15: 07 - Gov. Federal - CODEVASF | J15: Juazeiro | M15: 118800000 | Q15: =SUM(PAC!$M15:$P15) -> 118800000 | W15: =IF(PAC!$V15>0,PAC!$V15,PAC!$Q15) -> 118800000 | Y15: OGU | AA15: 26 | AB15: F03 - EXECUÇÃO DO OBJETO | AC15: 03 - AGUARDANDO ORDEM DE SERVIÇO | AG15: · Alocação da dotação orçamentária necessária para a cobertura da despesa; | AI15: Acompanhamento das obras (Codevasf) | AX15: Regime de Execução: Contratação Semi-Integrada; Extrato de contrato publicado no DOU de 21/01/25 - Empresa: Consórcio Construtor Sertão Baiano - CCSB, formado pelas empresas ÁLYA Construroa SA e Ankara Engenharia Ltda. - Valor: R$ 118.800.000,00; - Prazo de execução: 780 dias. | AY15: Ordem de Serviço dada pelo Presidente Lula em 07/02/25. | BB15: =IFERROR(IF(PAC!$AB15="F01 - CAPTAÇÃO DE RECURSO",1,""),"") | BC15: =IFERROR(IF(PAC!$AB15="F02 - LICITAÇÃO",1,""),"") | BD15: =IFERROR(IF(PAC!$AB$6:$AB$581="F03 - EXECUÇÃO DO OBJETO",1,""),"") -> 1 | BE15: =IFERROR(IF(PAC!$AB$6:$AB$581="F04 - CONCLUÍDA",1,""),"") | BF15: =IF(PAC!$V15>0,0,PAC!$Q15) -> 118800000
A16: =ROW()-5 -> 11 | B16: 2023 | C16: OBRA | D16: PAC SELEÇÕES | E16: Centro de Parto Natural - CPN | F16: Saúde | G16: Centro de Parto | H16: SESAB | I16: 11 - Gov. Estado - SESAB | J16: Ibotirama | L16: 5000000 | M16: 2588139.3 | Q16: =SUM(PAC!$M16:$P16) -> 2588139.3 | V16: 3058146.1 | W16: =IF(PAC!$V16>0,PAC!$V16,PAC!$Q16) -> 3058146.1 | X16: TRILHO ENGENHARIA LTDA | Y16: OGU | AA16: 8 | AB16: F04 - CONCLUÍDA | AC16: 18 - INAUGURADA | AD16: 46094 | AE16: 100 | AI16: - | AJ16: 36000001398/2023 | AO16: https://governodabahia.plataformatarget.com.br/web/a1f7de2e-8d06-4853-ace4-410ad9ffb441/home | AP16: https://maps.app.goo.gl/ZmoJFNyGgdYQ2TP58 | AR16: 45588 | AS16: 45639 | AT16: 45714 | AU16: 45727 | AV16: 45969 | AW16: 46094 | AX16: Valor apoiado pelo Ministério da Saúde: R$3.100.000,00 Planilha orçamentária: R$3.449.948,73 Inaugurada em 22/05/2026 | BA16: OBRA - Projeto Padrão | BB16: =IFERROR(IF(PAC!$AB16="F01 - CAPTAÇÃO DE RECURSO",1,""),"") | BC16: =IFERROR(IF(PAC!$AB16="F02 - LICITAÇÃO",1,""),"") | BD16: =IFERROR(IF(PAC!$AB$6:$AB$581="F03 - EXECUÇÃO DO OBJETO",1,""),"") | BE16: =IFERROR(IF(PAC!$AB$6:$AB$581="F04 - CONCLUÍDA",1,""),"") -> 1 | BF16: =IF(PAC!$V16>0,0,PAC!$Q16) -> 0
A17: =ROW()-5 -> 12 | B17: 2026 | C17: OBRA | D17: PAC SELEÇÕES | E17: Centro Especializado em Reabilitação - CER, Tipo IV | F17: Saúde | G17: CER | H17: SESAB | I17: 11 - Gov. Estado - SESAB | J17: Camaçari | M17: 13847802 | Q17: =SUM(PAC!$M17:$P17) -> 13847802 | V17: 13847802 | W17: =IF(PAC!$V17>0,PAC!$V17,PAC!$Q17) -> 13847802 | X17: Holtz Engenharia Ltda | Y17: OGU | AA17: 10 | AB17: F03 - EXECUÇÃO DO OBJETO | AC17: 02 - ANDAMENTO | AD17: 46472 | AE17: 13 | AF17: Execução da Obra | AG17: Monitorar execução da obra. | AI17: Monitoramento da execução da obra. | AK17: 05816.6300001/25-006 | AP17: https://maps.app.goo.gl/kkjkEj2YgvwCVFmd6?g_st=iw | AR17: 46095 | AS17: 46153 | AT17: 46167 | AU17: 46169 | AV17: 46472 | AW17: 46472 | BA17: OBRA - Projeto Padrão | BB17: =IFERROR(IF(PAC!$AB17="F01 - CAPTAÇÃO DE RECURSO",1,""),"") | BC17: =IFERROR(IF(PAC!$AB17="F02 - LICITAÇÃO",1,""),"") | BD17: =IFERROR(IF(PAC!$AB$6:$AB$581="F03 - EXECUÇÃO DO OBJETO",1,""),"") -> 1 | BE17: =IFERROR(IF(PAC!$AB$6:$AB$581="F04 - CONCLUÍDA",1,""),"") | BF17: =IF(PAC!$V17>0,0,PAC!$Q17) -> 0
A18: =ROW()-5 -> 13 | B18: 2026 | C18: OBRA | D18: PAC SELEÇÕES | E18: Centro Especializado em Reabilitação - CER, Tipo IV | F18: Saúde | G18: CER | H18: SESAB | I18: 11 - Gov. Estado - SESAB | J18: Juazeiro | M18: 12532185 | Q18: =SUM(PAC!$M18:$P18) -> 12532185 | V18: 12532185 | W18: =IF(PAC!$V18>0,PAC!$V18,PAC!$Q18) -> 12532185 | X18: Nove Engenharia LTDA | Y18: OGU | AA18: 10 | AB18: F03 - EXECUÇÃO DO OBJETO | AC18: 02 - ANDAMENTO | AD18: 46485 | AE18: 6 | AF18: Execução da Obra | AG18: Monitorar execução da obra. | AI18: Monitoramento da execução da obra. | AK18: 05816.6300001/25-007 | AP18: https://maps.app.goo.gl/2UqqijCSWKzvdqb67?g_st=iw | AR18: 46095 | AS18: 46155 | AT18: 46185 | AU18: 46185 | AV18: 46485 | AW18: 46485 | BA18: OBRA - Projeto Padrão | BB18: =IFERROR(IF(PAC!$AB18="F01 - CAPTAÇÃO DE RECURSO",1,""),"") | BC18: =IFERROR(IF(PAC!$AB18="F02 - LICITAÇÃO",1,""),"") | BD18: =IFERROR(IF(PAC!$AB$6:$AB$581="F03 - EXECUÇÃO DO OBJETO",1,""),"") -> 1 | BE18: =IFERROR(IF(PAC!$AB$6:$AB$581="F04 - CONCLUÍDA",1,""),"") | BF18: =IF(PAC!$V18>0,0,PAC!$Q18) -> 0
A19: =ROW()-5 -> 14 | B19: 2026 | C19: OBRA | D19: PAC SELEÇÕES | E19: Centro Especializado em Reabilitação - CER, Tipo IV | F19: Saúde | G19: CER | H19: SESAB | I19: 11 - Gov. Estado - SESAB | J19: Conceição do Coité | M19: 12030678 | Q19: =SUM(PAC!$M19:$P19) -> 12030678 | V19: 12030678 | W19: =IF(PAC!$V19>0,PAC!$V19,PAC!$Q19) -> 12030678 | X19: Holtz Engenharia Ltda | Y19: OGU | AA19: 10 | AB19: F03 - EXECUÇÃO DO OBJETO | AC19: 02 - ANDAMENTO | AD19: 46562 | AE19: 0 | AF19: Execução da Obra | AG19: Monitorar execução da obra. | AI19: Monitoramento da execução da obra. | AK19: 05816.6300001/25-012 | AP19: https://maps.app.goo.gl/twd22R7g9MUY82N87?g_st=iw | AR19: 46095 | AS19: 46157 | AT19: 46256 | AU19: 46258 | AV19: 46562 | AW19: 46562 | BA19: OBRA - Projeto Padrão | BB19: =IFERROR(IF(PAC!$AB19="F01 - CAPTAÇÃO DE RECURSO",1,""),"") | BC19: =IFERROR(IF(PAC!$AB19="F02 - LICITAÇÃO",1,""),"") | BD19: =IFERROR(IF(PAC!$AB$6:$AB$581="F03 - EXECUÇÃO DO OBJETO",1,""),"") -> 1 | BE19: =IFERROR(IF(PAC!$AB$6:$AB$581="F04 - CONCLUÍDA",1,""),"") | BF19: =IF(PAC!$V19>0,0,PAC!$Q19) -> 0
A20: =ROW()-5 -> 15 | B20: 2023 | C20: OBRA | D20: PAC SELEÇÕES | E20: Construção do CEU da Cultura | F20: Turismo e Cultura | G20: CEU da Cultura | H20: SECULT | I20: 14 - Gov. Estado - CONDER | J20: Camaçari | M20: 2066482.2 | O20: 718166.39 | Q20: =SUM(PAC!$M20:$P20) -> 2784648.6 | V20: 3251366.2 | W20: =IF(PAC!$V20>0,PAC!$V20,PAC!$Q20) -> 3251366.2 | Y20: OGU COMPLEMENTAR | AA20: 8 | AB20: F02 - LICITAÇÃO | AC20: 03 - AGUARDANDO ORDEM DE SERVIÇO | AF20: Homologar e Adjudicar Licitação | AI20: *VRPL *AIO *OS *Execução da Obra | AJ20: 005325/2024 42000000020/2023 | AK20: 963515/2024 | AL20: 01 - Retirada Total | AO20: https://governodabahia.plataformatarget.com.br/web/daf5d385-da94-4a43-8508-bba423304821/home | AP20: https://maps.app.goo.gl/PyseNPsBHpBCHmAR8 | AR20: 46066 | AS20: 46148 | AX20: Ofício CE 46/2026 enviado em 04/02/2026 solicitando nova prorrogação de prazo para abertura de licitação dos CEUS da Cultura. Ofício CE 16/2026 enviado em 01/01/2026 comunicando conclusão da alteração de valores de Repasse nos Termos de Compromisso. Ofício CE 4680/2025 enviado em 17/10/2025 comunicando Celebração de Termo Aditivo (Adequação do valor de repasse - R$ 2.066.482,18 e inclusão dos valores para aquisição de equipamentos e mobiliários - R$ 492.646,42). Valor Total: R$ 2.559.128,60. | AY20: Empresas Participantes - ART Projetos Construções e Serviços LTDA Consórcio F&R Cultura LP 020 - FCK contruções e Incorporações LTDA / ROBLE Serviços LTDA IFC Engenharia LTDA Consórcio Faria Lima - L3 - CEU CULTURA - Contrutora Faria Lima / Leite Engenharia e Consultoria LTDA Aviso de Licitação publicado no DOE 13/02/26 - Abertura 06/05/26 À Licitar. Ofício CE 19/2026 enviado em 02/01/2026 prorrogando abertura da Licitação para 28/02/2026. 19/11/25 - Aguardando dotação orçamentária para licitar. Elaboração de TR e Edital. (Aguardando Secult definir recurso complementar) (Elaboração de projeto técnico pela conder com previsão até 31/10/25) | BA20: OBRA - Projeto Padrão | BB20: =IFERROR(IF(PAC!$AB20="F01 - CAPTAÇÃO DE RECURSO",1,""),"") | BC20: =IFERROR(IF(PAC!$AB20="F02 - LICITAÇÃO",1,""),"") -> 1 | BD20: =IFERROR(IF(PAC!$AB$6:$AB$581="F03 - EXECUÇÃO DO OBJETO",1,""),"") | BE20: =IFERROR(IF(PAC!$AB$6:$AB$581="F04 - CONCLUÍDA",1,""),"") | BF20: =IF(PAC!$V20>0,0,PAC!$Q20) -> 0
A21: =ROW()-5 -> 16 | B21: 2023 | C21: OBRA | D21: PAC SELEÇÕES | E21: Construção do CEU da Cultura | F21: Turismo e Cultura | G21: CEU da Cultura | H21: SECULT | I21: 14 - Gov. Estado - CONDER | J21: Catu | M21: 2066482.2 | O21: 333538.4 | Q21: =SUM(PAC!$M21:$P21) -> 2400020.6 | V21: 2716453.2 | W21: =IF(PAC!$V21>0,PAC!$V21,PAC!$Q21) -> 2716453.2 | Y21: OGU CONTRAPARTIDA COMPLEMENTAR | AA21: 8 | AB21: F02 - LICITAÇÃO | AC21: 03 - AGUARDANDO ORDEM DE SERVIÇO | AF21: Homologar e Adjudicar Licitação | AI21: *VRPL *AIO *OS *Execução da Obra | AJ21: 005341/2024 42000000335/2023 | AK21: 963558/2024 | AL21: 01 - Retirada Total | AO21: https://governodabahia.plataformatarget.com.br/web/ecd0e843-18de-4c76-abdd-2638559a3ca9/home | AP21: https://maps.app.goo.gl/yEPv7EZEEjr875vV9 | AR21: 46066 | AS21: 46148 | AX21: Ofício CE 46/2026 enviado em 04/02/2026 solicitando nova prorrogação de prazo para abertura de licitação dos CEUS da Cultura. Ofício CE 16/2026 enviado em 01/01/2026 comunicando conclusão da alteração de valores de Repasse nos Termos de Compromisso. Ofício CE 4680/2025 enviado em 17/10/2025 comunicando Celebração de Termo Aditivo (Adequação do valor de repasse - R$ 2.066.482,18 e inclusão dos valores para aquisição de equipamentos e mobiliários - R$ 492.646,42). Valor Total: R$ 2.559.128,60. CE Gigov 2408/2025 solicitação de complementação. Terrenos definidos e tecnicamente aprovados/ Projetos em desenvolvimento. Atendimento as pendências para retirada da Cláusula suspensiva. | AY21: Empresas Participantes -ART Projetos Construções e Serviços LTDA Consórcio F&R Cultura LP 020 - FCK contruções e Incorporações LTDA / ROBLE Serviços LTDA IFC Engenharia LTDA Consórcio Faria Lima - L3 - CEU CULTURA - Contrutora Faria Lima / Leite Engenharia e Consultoria LTDA Aviso de Licitação publicado no DOE 13/02/26 - Abertura 06/05/26 À Licitar. Ofício CE 19/2026 enviado em 02/01/2026 prorrogando abertura da Licitação para 28/02/2026. 19/11/25 - Aguardando dotação orçamentária para licitar. | BA21: OBRA - Projeto Padrão | BB21: =IFERROR(IF(PAC!$AB21="F01 - CAPTAÇÃO DE RECURSO",1,""),"") | BC21: =IFERROR(IF(PAC!$AB21="F02 - LICITAÇÃO",1,""),"") -> 1 | BD21: =IFERROR(IF(PAC!$AB$6:$AB$581="F03 - EXECUÇÃO DO OBJETO",1,""),"") | BE21: =IFERROR(IF(PAC!$AB$6:$AB$581="F04 - CONCLUÍDA",1,""),"") | BF21: =IF(PAC!$V21>0,0,PAC!$Q21) -> 0
A22: =ROW()-5 -> 17 | B22: 2023 | C22: OBRA | D22: PAC SELEÇÕES | E22: Construção do CEU da Cultura | F22: Turismo e Cultura | G22: CEU da Cultura | H22: SECULT | I22: 14 - Gov. Estado - CONDER | J22: Santo Amaro | M22: 2066482.2 | O22: 555569.94 | Q22: =SUM(PAC!$M22:$P22) -> 2622052.1 | V22: 3199451.6 | W22: =IF(PAC!$V22>0,PAC!$V22,PAC!$Q22) -> 3199451.6 | Y22: OGU CONTRAPARTIDA COMPLEMENTAR | AA22: 8 | AB22: F02 - LICITAÇÃO | AC22: 03 - AGUARDANDO ORDEM DE SERVIÇO | AF22: Homologar e Adjudicar Licitação | AI22: *VRPL *AIO *OS *Execução da Obra | AJ22: 005337/2024 42000000270/2023 | AK22: 963523/2024 | AL22: 01 - Retirada Total | AO22: https://governodabahia.plataformatarget.com.br/web/0d0a423d-c272-415d-b811-b0fe69a309e2/home | AP22: https://maps.app.goo.gl/RKehfZFMWzKqUiiq9 | AR22: 46066 | AS22: 46148 | AX22: Ofício CE 46/2026 enviado em 04/02/2026 solicitando nova prorrogação de prazo para abertura de licitação dos CEUS da Cultura. Ofício CE 16/2026 enviado em 01/01/2026 comunicando conclusão da alteração de valores de Repasse nos Termos de Compromisso. Ofício CE 4680/2025 enviado em 17/10/2025 comunicando Celebração de Termo Aditivo (Adequação do valor de repasse - R$ 2.066.482,18 e inclusão dos valores para aquisição de equipamentos e mobiliários - R$ 492.646,42). Valor Total: R$ 2.559.128,60. Emissão do LAE. A Conder elaborou um estudo preliminar, já ecaminhado e em posse do município, que atualmente se encontra em fase de planejamento, compatibilização e adequação dos elementos arquitetónicos passíveis de tal demandas e realidades locais. O terreno se locliza próximo á Ruínas do Irapuru muito relevante para memória regional. Terreno possui matrícula e escritura. Terrenos definidos e tecnicamente aprovados/ Projetos em desenvolvimento | AY22: Empresas Participantes -ART Projetos Construções e Serviços LTDA Consórcio F&R Cultura LP 020 - FCK contruções e Incorporações LTDA / ROBLE Serviços LTDA IFC Engenharia LTDA Consórcio Faria Lima - L3 - CEU CULTURA - Contrutora Faria Lima / Leite Engenharia e Consultoria LTDA Aviso de Licitação publicado no DOE 13/02/26 - Abertura 06/05/26 À Licitar. Ofício CE 19/2026 enviado em 02/01/2026 prorrogando abertura da Licitação para 28/02/2026. 19/11/25 - Aguardando dotação orçamentária para licitar. | BA22: OBRA - Projeto Padrão | BB22: =IFERROR(IF(PAC!$AB22="F01 - CAPTAÇÃO DE RECURSO",1,""),"") | BC22: =IFERROR(IF(PAC!$AB22="F02 - LICITAÇÃO",1,""),"") -> 1 | BD22: =IFERROR(IF(PAC!$AB$6:$AB$581="F03 - EXECUÇÃO DO OBJETO",1,""),"") | BE22: =IFERROR(IF(PAC!$AB$6:$AB$581="F04 - CONCLUÍDA",1,""),"") | BF22: =IF(PAC!$V22>0,0,PAC!$Q22) -> 0
A23: =ROW()-5 -> 18 | B23: 2023 | C23: OBRA | D23: PAC SELEÇÕES | E23: Construção do CEU da Cultura | F23: Turismo e Cultura | G23: CEU da Cultura | H23: SECULT | I23: 14 - Gov. Estado - CONDER | J23: Bom Jesus da Lapa | M23: 2066482.2 | O23: 289993.02 | Q23: =SUM(PAC!$M23:$P23) -> 2356475.2 | V23: 2541702.9 | W23: =IF(PAC!$V23>0,PAC!$V23,PAC!$Q23) -> 2541702.9 | X23: CONSÓRCIO TRILHO/FPE - (TRILHO ENGENHARIA LTDA / FÁBIO PERA ARQUITETO LTDA) | Y23: OGU CONTRAPARTIDA COMPLEMENTAR | AA23: 8 | AB23: F03 - EXECUÇÃO DO OBJETO | AC23: 02 - ANDAMENTO | AF23: Emissão do aceite VRPL | AG23: Conder enviar documentação para Caixa para obtenção do VRPL | AI23: *VRPL *AIO *OS *Execução da Obra | AJ23: 005327/2024 42000000025/2023 | AK23: 963522/2024 | AL23: 01 - Retirada Total | AO23: https://governodabahia.plataformatarget.com.br/web/bb718052-2b62-4143-ba89-4f1b5cf64f96/home | AP23: https://maps.app.goo.gl/KURtToAEqZ99jEFF6 | AR23: 46066 | AS23: 46147 | AT23: 46239 | AX23: 07/10/26 - SERVIÇOS CONCLUÍDOS: Instalação de placa de obra. SERVIÇO À INICIAR: Instalação de Tapume metálico (PREVISÃO: 13/10/2026); Serviços Preliminares; Terraplenagem ; Elaboração de Projetos; Fundações; Superestrutura; Cobertura; Paredes e painéis; Esquadrias; Sistemas hidráulicos, Sanitários e de combate a incêndio(HSI); Sistema elétrico e sistema de voz e dados; Sistemas de ar condicionado, ventilação e exaustão; Revestimentos primários; Acabamentos (revestimento para teto, parede e piso); Acabamentos (hidrossanitários); Acabamentos (elétricos, voz, dados e tv); Pintura; Urbanização e paisagismo; Desmobilização de canteiro e Limpeza final. Obs.: A empresa está em processo de elaboração dos projetos executivos, previsão para iniciar a obra após a aprovação. Ofício CE 46/2026 enviado em 04/02/2026 solicitando nova prorrogação de prazo para abertura de licitação dos CEUS da Cultura. Ofício CE 16/2026 enviado em 01/01/2026 comunicando conclusão da alteração de valores de Repasse nos Termos de Compromisso. Ofício CE 4680/2025 enviado em 17/10/2025 comunicando Celebração de Termo Aditivo (Adequação do valor de repasse - R$ 2.066.482,18 e inclusão dos valores para aquisição de equipamentos e mobiliários - R$ 492.646,42). Valor Total: R$ 2.559.128,60. Solicitação de ordenador de despesas 043.4110.2025.0017422-24 enviado para SECULT em 07/10/2025. Terrenos definidos e tecnicamente aprovados/ Projetos aprovados possíveis de licitação | AY23: NOTIFICAÇÃO DE RECURSO DA LICITAÇÃO PRESENCIAL Nº 019/26 - SERRA DO RAMALHO, BOM JESUS DA LAPA, MACAÚBAS E SEABRA - CONDER - publicada no DOE em 21/07/2026 Empresas participantes Consórcio TRILHO/FPE ( Trilho engenharia LTDA/ Fábio Pera arquiteto LTDA) e ART projetos construções e serviços LTDA Aviso de Licitação publicado no DOE 13/02/26 - Abertura 05/05/26 À Licitar. Ofício CE 19/2026 enviado em 02/01/2026 prorrogando abertura da Licitação para 28/02/2026. 19/11/25 - Aguardando dotação orçamentária para licitar. | BA23: OBRA - Projeto Padrão | BB23: =IFERROR(IF(PAC!$AB23="F01 - CAPTAÇÃO DE RECURSO",1,""),"") | BC23: =IFERROR(IF(PAC!$AB23="F02 - LICITAÇÃO",1,""),"") | BD23: =IFERROR(IF(PAC!$AB$6:$AB$581="F03 - EXECUÇÃO DO OBJETO",1,""),"") -> 1 | BE23: =IFERROR(IF(PAC!$AB$6:$AB$581="F04 - CONCLUÍDA",1,""),"") | BF23: =IF(PAC!$V23>0,0,PAC!$Q23) -> 0
A24: =ROW()-5 -> 19 | B24: 2023 | C24: OBRA | D24: PAC SELEÇÕES | E24: Construção do CEU da Cultura | F24: Turismo e Cultura | G24: CEU da Cultura | H24: SECULT | I24: 14 - Gov. Estado - CONDER | J24: Macaúbas | M24: 2066482.2 | O24: 506924.27 | Q24: =SUM(PAC!$M24:$P24) -> 2573406.5 | V24: 2889910.7 | W24: =IF(PAC!$V24>0,PAC!$V24,PAC!$Q24) -> 2889910.7 | X24: CONSÓRCIO TRILHO/FPE - (TRILHO ENGENHARIA LTDA / FÁBIO PERA ARQUITETO LTDA) | Y24: OGU CONTRAPARTIDA COMPLEMENTAR | AA24: 8 | AB24: F03 - EXECUÇÃO DO OBJETO | AC24: 02 - ANDAMENTO | AF24: Emissão do aceite VRPL | AG24: Conder enviar documentação para Caixa para obtenção do VRPL | AI24: *VRPL *AIO *OS *Execução da Obra | AJ24: 005343/2024 42000000343/2023 | AK24: 963561/2024 | AL24: 01 - Retirada Total | AO24: https://governodabahia.plataformatarget.com.br/web/81a0d0b6-c095-4caa-b78d-0655b42caed5/home | AP24: https://maps.app.goo.gl/YycXB4MzLASDnNFS8 | AR24: 46066 | AS24: 46147 | AT24: 46239 | AX24: 07/10/26 -SERVIÇO À INICIAR: Instalação de placa de obra; Instalação de Tapume metálico ; Serviços Preliminares; Terraplenagem ; Elaboração de Projetos; Fundações; Superestrutura; Cobertura; Paredes e painéis; Esquadrias; Sistemas hidráulicos, Sanitários e de combate a incêndio(HSI); Sistema elétrico e sistema de voz e dados; Sistemas de ar condicionado, ventilação e exaustão; Revestimentos primários; Acabamentos (revestimento para teto, parede e piso); Acabamentos (hidrossanitários); Acabamentos (elétricos, voz, dados e tv); Pintura; Urbanização e paisagismo; Desmobilização de canteiro e Limpeza final. Obs.: A prefeitura está fazendo a permuta do terreno. Ofício CE 46/2026 enviado em 04/02/2026 solicitando nova prorrogação de prazo para abertura de licitação dos CEUS da Cultura. Ofício CE 16/2026 enviado em 01/01/2026 comunicando conclusão da alteração de valores de Repasse nos Termos de Compromisso. Ofício CE 4680/2025 enviado em 17/10/2025 comunicando Celebração de Termo Aditivo (Adequação do valor de repasse - R$ 2.066.482,18 e inclusão dos valores para aquisição de equipamentos e mobiliários - R$ 492.646,42). Valor Total: R$ 2.559.128,60. Solicitação de ordenador de despesas 043.4110.2025.0017422-24 enviado para SECULT em 07/10/2025. Terreno indicada não cabe, mas há espaço para ampliação, foi solicitada ajuste da poligonal. Conclusão automática da SPA. Aguardando autorização pela Caixa para licitar. Aguardando definição de recurso compelementar pela Secult. Elaboração de TR e Edital. | AY24: NOTIFICAÇÃO DE RECURSO DA LICITAÇÃO PRESENCIAL Nº 019/26 - SERRA DO RAMALHO, BOM JESUS DA LAPA, MACAÚBAS E SEABRA - CONDER - publicada no DOE em 21/07/2026 Empresas participantes Consórcio TRILHO/FPE ( Trilho engenharia LTDA/ Fábio Pera arquiteto LTDA) e ART projetos construções e serviços LTDA Aviso de Licitação publicado no DOE 13/02/26 - Abertura 05/05/26 À Licitar. Ofício CE 19/2026 enviado em 02/01/2026 prorrogando abertura da Licitação para 28/02/2026. 19/11/25 - Aguardando dotação orçamentária para licitar. | BA24: OBRA - Projeto Padrão | BB24: =IFERROR(IF(PAC!$AB24="F01 - CAPTAÇÃO DE RECURSO",1,""),"") | BC24: =IFERROR(IF(PAC!$AB24="F02 - LICITAÇÃO",1,""),"") | BD24: =IFERROR(IF(PAC!$AB$6:$AB$581="F03 - EXECUÇÃO DO OBJETO",1,""),"") -> 1 | BE24: =IFERROR(IF(PAC!$AB$6:$AB$581="F04 - CONCLUÍDA",1,""),"") | BF24: =IF(PAC!$V24>0,0,PAC!$Q24) -> 0
A25: =ROW()-5 -> 20 | B25: 2023 | C25: OBRA | D25: PAC SELEÇÕES | E25: Construção do CEU da Cultura | F25: Turismo e Cultura | G25: CEU da Cultura | H25: SECULT | I25: 14 - Gov. Estado - CONDER | J25: Dias D'Ávila | M25: 2066482.2 | O25: 2034674.3 | Q25: =SUM(PAC!$M25:$P25) -> 4101156.5 | V25: 2913740.5 | W25: =IF(PAC!$V25>0,PAC!$V25,PAC!$Q25) -> 2913740.5 | X25: ROBLE SERVIÇOS LTDA e FCK CONSTRUÇÕES E INCORPORAÇÕES LTDA | Y25: OGU CONTRAPARTIDA COMPLEMENTAR | AA25: 8 | AB25: F02 - LICITAÇÃO | AC25: 03 - AGUARDANDO ORDEM DE SERVIÇO | AF25: Homologar e Adjudicar Licitação | AI25: *VRPL *AIO *OS *Execução da Obra | AK25: 963496/2024 | AL25: 01 - Retirada Total | AR25: 46066 | AS25: 46146 | AT25: 46224 | AX25: Notificação de Recurso publicada no DOE 27/06/2026 Ofício CE 46/2026 enviado em 04/02/2026 solicitando nova prorrogação de prazo para abertura de licitação dos CEUS da Cultura. Ofício CE 16/2026 enviado em 01/01/2026 comunicando conclusão da alteração de valores de Repasse nos Termos de Compromisso. Ofício CE 4680/2025 enviado em 17/10/2025 comunicando Celebração de Termo Aditivo (Adequação do valor de repasse - R$ 2.066.482,18 e inclusão dos valores para aquisição de equipamentos e mobiliários - R$ 492.646,42). Valor Total: R$ 2.559.128,60. | AY25: Empresas participantes -INO9VARE Enganharia LTDA Consórcio F&R Cultura LP 017 - FCK contruções e Incorporações LTDA / ROBLE Serviços LTDA Aviso de Licitação publicado no DOE 13/02/26 - Abertura 04/05/26 À Licitar. Ofício CE 19/2026 enviado em 02/01/2026 prorrogando abertura da Licitação para 28/02/2026. 19/11/25 - Aguardando dotação orçamentária para licitar. | BA25: OBRA - Projeto Padrão | BB25: =IFERROR(IF(PAC!$AB25="F01 - CAPTAÇÃO DE RECURSO",1,""),"") | BC25: =IFERROR(IF(PAC!$AB25="F02 - LICITAÇÃO",1,""),"") -> 1 | BD25: =IFERROR(IF(PAC!$AB$6:$AB$581="F03 - EXECUÇÃO DO OBJETO",1,""),"") | BE25: =IFERROR(IF(PAC!$AB$6:$AB$581="F04 - CONCLUÍDA",1,""),"") | BF25: =IF(PAC!$V25>0,0,PAC!$Q25) -> 0
A26: =ROW()-5 -> 21 | B26: 2023 | C26: OBRA | D26: PAC SELEÇÕES | E26: Construção do CEU da Cultura | F26: Turismo e Cultura | G26: CEU da Cultura | H26: SECULT | I26: 14 - Gov. Estado - CONDER | J26: Senhor do Bonfim | M26: 2066482.2 | O26: 368521.17 | Q26: =SUM(PAC!$M26:$P26) -> 2435003.4 | V26: 2617664.7 | W26: =IF(PAC!$V26>0,PAC!$V26,PAC!$Q26) -> 2617664.7 | X26: ART PROJETOS CONSTRUÇÕES E SERVIÇOS LTDA. | Y26: OGU CONTRAPARTIDA COMPLEMENTAR | AA26: 8 | AB26: F02 - LICITAÇÃO | AC26: 03 - AGUARDANDO ORDEM DE SERVIÇO | AF26: Homologar e Adjudicar Licitação | AI26: *AIO *OS *Execução da Obra | AJ26: 005329/2024 42000000028/2023 | AK26: 963474/2024 | AL26: 01 - Retirada Total | AO26: https://governodabahia.plataformatarget.com.br/web/a7cf4c50-61a0-435a-94b6-47c954241d7a/home | AP26: https://maps.app.goo.gl/Rrn4cPWUu2apobkQ6 | AR26: 46066 | AS26: 46147 | AX26: Ofício CE 46/2026 enviado em 04/02/2026 solicitando nova prorrogação de prazo para abertura de licitação dos CEUS da Cultura. Ofício CE 16/2026 enviado em 01/01/2026 comunicando conclusão da alteração de valores de Repasse nos Termos de Compromisso. Ofício CE 4680/2025 enviado em 17/10/2025 comunicando Celebração de Termo Aditivo (Adequação do valor de repasse - R$ 2.066.482,18 e inclusão dos valores para aquisição de equipamentos e mobiliários - R$ 492.646,42). Valor Total: R$ 2.559.128,60. Solicitação de Ordenador de Despesas 043.4110.2025.0018290-01 enviado para SECULT em 13/10/2025. Terrenos definidos e tecnicamente aprovados/ Projetos em desenvolvimento visando licitação. | AY26: Empresas participantes - ART Projetos Construções e Serviços LTDA Consórcio F&R Cultura LP 018 - FCK contruções e Incorporações LTDA / ROBLE Serviços LTDA IFC Engenharia LTDA Aviso de Licitação publicado no DOE 13/02/26 - Abertura 05/05/26 À Licitar. Ofício CE 19/2026 enviado em 02/01/2026 prorrogando abertura da Licitação para 28/02/2026. 19/11/25 - Aguardando dotação orçamentária para licitar. | BA26: OBRA - Projeto Padrão | BB26: =IFERROR(IF(PAC!$AB26="F01 - CAPTAÇÃO DE RECURSO",1,""),"") | BC26: =IFERROR(IF(PAC!$AB26="F02 - LICITAÇÃO",1,""),"") -> 1 | BD26: =IFERROR(IF(PAC!$AB$6:$AB$581="F03 - EXECUÇÃO DO OBJETO",1,""),"") | BE26: =IFERROR(IF(PAC!$AB$6:$AB$581="F04 - CONCLUÍDA",1,""),"") | BF26: =IF(PAC!$V26>0,0,PAC!$Q26) -> 0
A27: =ROW()-5 -> 22 | B27: 2023 | C27: OBRA | D27: PAC SELEÇÕES | E27: Construção do CEU da Cultura | F27: Turismo e Cultura | G27: CEU da Cultura | H27: SECULT | I27: 14 - Gov. Estado - CONDER | J27: Jeremoabo | M27: 2066482.2 | O27: 349218.83 | Q27: =SUM(PAC!$M27:$P27) -> 2415701 | V27: 2579083.4 | W27: =IF(PAC!$V27>0,PAC!$V27,PAC!$Q27) -> 2579083.4 | X27: ART PROJETOS CONSTRUÇÕES E SERVIÇOS LTDA. | Y27: OGU CONTRAPARTIDA COMPLEMENTAR | AA27: 8 | AB27: F02 - LICITAÇÃO | AC27: 03 - AGUARDANDO ORDEM DE SERVIÇO | AF27: Homologar e Adjudicar Licitação | AI27: *AIO *OS *Execução da Obra | AJ27: 005331/2024 42000000037/2023 | AK27: 963492/2024 | AL27: 01 - Retirada Total | AO27: https://governodabahia.plataformatarget.com.br/web/84198b2e-bf78-44a9-9785-8e982953e691/home | AP27: https://maps.app.goo.gl/K2qcBkesDemh3P626 | AR27: 46066 | AS27: 46147 | AX27: Ofício CE 46/2026 enviado em 04/02/2026 solicitando nova prorrogação de prazo para abertura de licitação dos CEUS da Cultura.Ofício CE 46/2026 enviado em 04/02/2026 solicitando nova prorrogação de prazo para abertura de licitação dos CEUS da Cultura. Ofício CE 16/2026 enviado em 01/01/2026 comunicando conclusão da alteração de valores de Repasse nos Termos de Compromisso. Ofício CE 4680/2025 enviado em 17/10/2025 comunicando Celebração de Termo Aditivo (Adequação do valor de repasse - R$ 2.066.482,18 e inclusão dos valores para aquisição de equipamentos e mobiliários - R$ 492.646,42). Valor Total: R$ 2.559.128,60. Solicitação de Ordenador de Despesas 043.4110.2025.0018290-01 enviado para SECULT em 13/10/2025. Terrenos definidos e tecnicamente aprovados/ Projetos em desenvolvimento visando licitação. | AY27: Empresas participantes - ART Projetos Construções e Serviços LTDA Consórcio F&R Cultura LP 018 - FCK contruções e Incorporações LTDA / ROBLE Serviços LTDA IFC Engenharia LTDA Aviso de Licitação publicado no DOE 13/02/26 - Abertura 05/05/26 À Licitar. Ofício CE 19/2026 enviado em 02/01/2026 prorrogando abertura da Licitação para 28/02/2026. 19/11/25 - Aguardando dotação orçamentária para licitar. | BA27: OBRA - Projeto Padrão | BB27: =IFERROR(IF(PAC!$AB27="F01 - CAPTAÇÃO DE RECURSO",1,""),"") | BC27: =IFERROR(IF(PAC!$AB27="F02 - LICITAÇÃO",1,""),"") -> 1 | BD27: =IFERROR(IF(PAC!$AB$6:$AB$581="F03 - EXECUÇÃO DO OBJETO",1,""),"") | BE27: =IFERROR(IF(PAC!$AB$6:$AB$581="F04 - CONCLUÍDA",1,""),"") | BF27: =IF(PAC!$V27>0,0,PAC!$Q27) -> 0
A28: =ROW()-5 -> 23 | B28: 2023 | C28: OBRA | D28: PAC SELEÇÕES | E28: Construção do CEU da Cultura | F28: Turismo e Cultura | G28: CEU da Cultura | H28: SECULT | I28: 14 - Gov. Estado - CONDER | J28: Itiúba | M28: 2066482.2 | O28: 764378.48 | Q28: =SUM(PAC!$M28:$P28) -> 2830860.7 | V28: 2784091.1 | W28: =IF(PAC!$V28>0,PAC!$V28,PAC!$Q28) -> 2784091.1 | X28: ART PROJETOS CONSTRUÇÕES E SERVIÇOS LTDA. | Y28: OGU CONTRAPARTIDA COMPLEMENTAR | AA28: 8 | AB28: F02 - LICITAÇÃO | AC28: 03 - AGUARDANDO ORDEM DE SERVIÇO | AF28: Homologar e Adjudicar Licitação | AI28: *AIO *OS *Execução da Obra | AJ28: 005342/2024 42000000342/2023 | AK28: 963560/2024 | AL28: 01 - Retirada Total | AO28: https://governodabahia.plataformatarget.com.br/web/e8527da7-efa1-44ce-b2f3-61e7763c258d/home | AP28: https://maps.app.goo.gl/PG5xfUpR8YuzVnWm9 | AR28: 46066 | AS28: 46147 | AX28: Ofício CE 46/2026 enviado em 04/02/2026 solicitando nova prorrogação de prazo para abertura de licitação dos CEUS da Cultura. Ofício CE 46/2026 enviado em 04/02/2026 solicitando nova prorrogação de prazo para abertura de licitação dos CEUS da Cultura. Ofício CE 16/2026 enviado em 01/01/2026 comunicando conclusão da alteração de valores de Repasse nos Termos de Compromisso. Ofício CE 4680/2025 enviado em 17/10/2025 comunicando Celebração de Termo Aditivo (Adequação do valor de repasse - R$ 2.066.482,18 e inclusão dos valores para aquisição de equipamentos e mobiliários - R$ 492.646,42). Valor Total: R$ 2.559.128,60. Solicitação de Ordenador de Despesas 043.4110.2025.0018290-01 enviado para SECULT em 13/10/2025. Terrenos definidos e tecnicamente aprovados/ Projetos em desenvolvimento visando licitação. | AY28: Empresas participantes - ART Projetos Construções e Serviços LTDA Consórcio F&R Cultura LP 018 - FCK contruções e Incorporações LTDA / ROBLE Serviços LTDA IFC Engenharia LTDA Aviso de Licitação publicado no DOE 13/02/26 - Abertura 05/05/26 À Licitar. Ofício CE 19/2026 enviado em 02/01/2026 prorrogando abertura da Licitação para 28/02/2026. 19/11/25 - Aguardando dotação orçamentária para licitar. | BA28: OBRA - Projeto Padrão | BB28: =IFERROR(IF(PAC!$AB28="F01 - CAPTAÇÃO DE RECURSO",1,""),"") | BC28: =IFERROR(IF(PAC!$AB28="F02 - LICITAÇÃO",1,""),"") -> 1 | BD28: =IFERROR(IF(PAC!$AB$6:$AB$581="F03 - EXECUÇÃO DO OBJETO",1,""),"") | BE28: =IFERROR(IF(PAC!$AB$6:$AB$581="F04 - CONCLUÍDA",1,""),"") | BF28: =IF(PAC!$V28>0,0,PAC!$Q28) -> 0
A29: =ROW()-5 -> 24 | B29: 2023 | C29: OBRA | D29: PAC SELEÇÕES | E29: Construção do CEU da Cultura | F29: Turismo e Cultura | G29: CEU da Cultura | H29: SECULT | I29: 14 - Gov. Estado - CONDER | J29: Juazeiro | M29: 2066482.2 | O29: 361079.96 | Q29: =SUM(PAC!$M29:$P29) -> 2427562.1 | V29: 2667050.3 | W29: =IF(PAC!$V29>0,PAC!$V29,PAC!$Q29) -> 2667050.3 | X29: ART PROJETOS CONSTRUÇÕES E SERVIÇOS LTDA. | Y29: OGU CONTRAPARTIDA COMPLEMENTAR | AA29: 8 | AB29: F02 - LICITAÇÃO | AC29: 03 - AGUARDANDO ORDEM DE SERVIÇO | AF29: Homologar e Adjudicar Licitação | AI29: *AIO *OS *Execução da Obra | AJ29: 005338/2024 42000000290/2023 | AK29: 963526/2024 | AL29: 01 - Retirada Total | AO29: https://governodabahia.plataformatarget.com.br/web/d9359efa-cc67-4a4f-87ce-ef74c9cd6bce/home | AP29: https://maps.app.goo.gl/kBMMoG4jJaEiZ3B59 | AR29: 46066 | AS29: 46147 | AX29: Ofício CE 46/2026 enviado em 04/02/2026 solicitando nova prorrogação de prazo para abertura de licitação dos CEUS da Cultura. Ofício CE 16/2026 enviado em 01/01/2026 comunicando conclusão da alteração de valores de Repasse nos Termos de Compromisso. Ofício CE 4680/2025 enviado em 17/10/2025 comunicando Celebração de Termo Aditivo (Adequação do valor de repasse - R$ 2.066.482,18 e inclusão dos valores para aquisição de equipamentos e mobiliários - R$ 492.646,42). Valor Total: R$ 2.559.128,60. Solicitação de Ordenador de Despesas 043.4110.2025.0018290-01 enviado para SECULT em 13/10/2025. A Conder elaborou um estudo preliminar, já ecaminhado e em posse do município, que atualmente se encontra em fase de planejamento, compatinilização e adequação dos elementos arquitetónicos passíveis de tal demandas e realidades locais. - Ce Gigov 2408/2025 solicitação de complementação. Terrenos definidos e tecnicamente aprovados/ Projetos em desenvolvimento visando licitação Atendimento as pendências para retirada da Cláusula suspensiva. | AY29: Empresas participantes - ART Projetos Construções e Serviços LTDA Consórcio F&R Cultura LP 018 - FCK contruções e Incorporações LTDA / ROBLE Serviços LTDA IFC Engenharia LTDA Aviso de Licitação publicado no DOE 13/02/26 - Abertura 05/05/26 À Licitar. Ofício CE 19/2026 enviado em 02/01/2026 prorrogando abertura da Licitação para 28/02/2026. 19/11/25 - Aguardando dotação orçamentária para licitar. | BA29: OBRA - Projeto Padrão | BB29: =IFERROR(IF(PAC!$AB29="F01 - CAPTAÇÃO DE RECURSO",1,""),"") | BC29: =IFERROR(IF(PAC!$AB29="F02 - LICITAÇÃO",1,""),"") -> 1 | BD29: =IFERROR(IF(PAC!$AB$6:$AB$581="F03 - EXECUÇÃO DO OBJETO",1,""),"") | BE29: =IFERROR(IF(PAC!$AB$6:$AB$581="F04 - CONCLUÍDA",1,""),"") | BF29: =IF(PAC!$V29>0,0,PAC!$Q29) -> 0
